Workbook

Sheet 1. Relevance (a)
A1: Relevance (a)
A2: If this hypothesis is true, how much of an impact is it having on the population?
A3: Consider 1) the extent of the threat on the hypothesized demographic parameter(s), 2) the sensitivity of population trend to the hypothesized demographic parameters, and 3) the overall effect, given 1 and 2, on the population trend (i.e., the mean rate of growth or decline in the population across time).
A4: Answer conditional on levels of the threat over the coming 30 years when evaluating this.
A5: For threats that are potential (i.e., are not currently present), score this question as the threat risk, which is the product of the likelihood of the threat occurring and the potential magnitude of its impact.
A6: Score of 0: even if true, this hypothesis has no to very little impact on the population.
A7: Score of 1: if true, this hypothesis has a small to moderate impact on the population, with an impact that is approximately 25% compared to the total range of variability in population trend.
A8: Score of 2: if true, this hypothesis has a moderate impact on the population, with an impact that is approximately 50% compared to the total range of variability in population trend.
A9: Score of 3: if true, this hypothesis has a moderate to large impact on the population, with an impact that is approximately 75% compared to the total range of variability in population trend.
A10: Score of 4: if true, this hypothesis has a large impact on the population, with an impact as large as the total range of variability in population trend.
A11: Disturbance
A12: Hypothesis 1: Low overflights disturb breeding colonies and reduce reproductive success.
B13: ASSP Relevance (a) score: | C13: 0
B14: BRPE Relevance (a) score: | C14: 1
B15: SCMU Relevance (a) score: | C15: 0
B16: SNPL Relevance (a) score: | C16: 0
B17: WEGU Relevance (a) score: | C17: 1
B18: CAAU Relevance (a) score: | C18: 0 | D18: OPTIONAL
A19: Hypothesis 2: Recreation causes disturbance to breeding colonies and reduces reproductive success.
B20: ASSP Relevance (a) score: | C20: 3
B21: BRPE Relevance (a) score: | C21: 3
B22: SCMU Relevance (a) score: | C22: 2
B23: SNPL Relevance (a) score: | C23: 3
B24: WEGU Relevance (a) score: | C24: 2
B25: CAAU Relevance (a) score: | C25: 2 | D25: OPTIONAL
A26: Fisheries
A27: Hypothesis 3: Commercial and recreational fishery equipment entangles/entraps individuals and reduces juvenile survival and/or adult survival.
B28: ASSP Relevance (a) score: | C28: 2
B29: BRPE Relevance (a) score: | C29: 4
B30: SCMU Relevance (a) score: | C30: 3
B31: SNPL Relevance (a) score: | C31: 0
B32: WEGU Relevance (a) score: | C32: 3
B33: CAAU Relevance (a) score: | C33: 2 | D33: OPTIONAL
A34: Hypothesis 4: Overfishing from commercial and recreational fisheries reduces foraging availability and/or quality, which reduces reproductive success, juvenile survival and/or adult survival.
B35: ASSP Relevance (a) score: | C35: 2
B36: BRPE Relevance (a) score: | C36: 4
B37: SCMU Relevance (a) score: | C37: 2
B38: SNPL Relevance (a) score: | C38: 0
B39: WEGU Relevance (a) score: | C39: 1
B40: CAAU Relevance (a) score: | C40: 2 | D40: OPTIONAL
...

Sheet 2. Relevance (b)
A1: Relevance (b)
A2: If this hypothesis is true, what is the potential of management actions, listed or otherwise, to reduce the effect of this hypothesis on the population?
A3: Consider the availability of management actions (listed or otherwise) to address the threat as well as the likelihood that management actions would/could be fully and effectively implemented.
A4: You can find a list of actions previously developed in the ‘Potential management actions’ document.
A5: If you identify an additional available management action that could be used to mediate the effect of this hypothesis, please make note of it in the appropriate section below.
A6: Score of 0: management actions will have no to very little impact on the hypothesized effect.
A7: Score of 1: management actions will reduce the hypothesized effect on the population by approximately 25%.
A8: Score of 2: management actions will reduce the hypothesized effect on the population by approximately 50%.
A9: Score of 3: management actions will reduce the hypothesized effect on the population by approximately 75%.
A10: Score of 4: management actions will mostly or completely reduce the hypothesized effect.
A11: Disturbance
A12: Hypothesis 1: Low overflights disturb breeding colonies and reduce reproductive success.
B13: ASSP Relevance (b) score: | C13: =IF('1. Relevance (a)'!C13=0, "NA", "") -> NA
B14: BRPE Relevance (b) score: | C14: 3
B15: SCMU Relevance (b) score: | C15: =IF('1. Relevance (a)'!C15=0, "NA", "") -> NA
B16: SNPL Relevance (b) score: | C16: =IF('1. Relevance (a)'!C16=0, "NA", "") -> NA
B17: WEGU Relevance (b) score: | C17: 3
B18: CAAU Relevance (b) score: | C18: =IF('1. Relevance (a)'!C18=0, "NA", "") -> NA | D18: OPTIONAL
A19: Hypothesis 2: Recreation causes disturbance to breeding colonies and reduces reproductive success.
B20: ASSP Relevance (b) score: | C20: 3
B21: BRPE Relevance (b) score: | C21: 3
B22: SCMU Relevance (b) score: | C22: 3
B23: SNPL Relevance (b) score: | C23: 3
B24: WEGU Relevance (b) score: | C24: 3
B25: CAAU Relevance (b) score: | C25: 3 | D25: OPTIONAL
A26: If there were any other management actions not listed that you identified that might be sensible if a given Disturbance hypothesis were true, please include it below:
A28: Fisheries
A29: Hypothesis 3: Commercial and recreational fishery equipment entangles/entraps individuals and reduces juvenile survival and/or adult survival.
B30: ASSP Relevance (b) score: | C30: 1
B31: BRPE Relevance (b) score: | C31: 1
B32: SCMU Relevance (b) score: | C32: 1
B33: SNPL Relevance (b) score: | C33: =IF('1. Relevance (a)'!C31=0, "NA", "") -> NA
B34: WEGU Relevance (b) score: | C34: 1
B35: CAAU Relevance (b) score: | C35: 1 | D35: OPTIONAL
A36: Hypothesis 4: Overfishing from commercial and recreational fisheries reduces foraging availability and/or quality, which reduces reproductive success, juvenile survival and/or adult survival.
B37: ASSP Relevance (b) score: | C37: 3
B38: BRPE Relevance (b) score: | C38: 3
B39: SCMU Relevance (b) score: | C39: 3
B40: SNPL Relevance (b) score: | C40: =IF('1. Relevance (a)'!C38=0, "NA", "") -> NA
B41: WEGU Relevance (b) score: | C41: 3
...

Sheet 3. Magnitude of uncertainty
A1: Magnitude of uncertainty
A2: How uncertain are you about the validity of this hypothesis?
A3: Consider the degree to which you think this hypothesis is currently operating on the population as well as your uncertainty regarding the impact of this threat on the population.
A4: Score of 0: There is little to no uncertainty regarding whether this hypothesis is true or false, based on current knowledge, theory, personal experience, or other rationale.
A5: Score of 1: There is low to moderate uncertainty regarding whether this hypothesis is true or false.
A6: Score of 2: There is moderate uncertainty regarding whether this hypothesis is true or false.
A7: Score of 3: There is moderate to high uncertainty regarding whether this hypothesis is true or false.
A8: Score of 4: There is little to no information currently available to discern whether this hypothesis is true or false.
A9: Hypothesis 1: Low overflights disturb breeding colonies and reduce reproductive success.
B10: ASSP Magnitude of uncertainty score: | C10: =IF('1. Relevance (a)'!C13=0, "NA", "") -> NA
B11: BRPE Magnitude of uncertainty score: | C11: 0
B12: SCMU Magnitude of uncertainty score: | C12: =IF('1. Relevance (a)'!C15=0, "NA", "") -> NA
B13: SNPL Magnitude of uncertainty score: | C13: =IF('1. Relevance (a)'!C16=0, "NA", "") -> NA
B14: WEGU Magnitude of uncertainty score: | C14: 1
B15: CAAU Magnitude of uncertainty score: | C15: =IF('1. Relevance (a)'!C18=0, "NA", "") -> NA | D15: OPTIONAL
A16: Hypothesis 2: Recreation causes disturbance to breeding colonies and reduces reproductive success.
B17: ASSP Magnitude of uncertainty score: | C17: 0
B18: BRPE Magnitude of uncertainty score: | C18: 0
B19: SCMU Magnitude of uncertainty score: | C19: 0
B20: SNPL Magnitude of uncertainty score: | C20: 2
B21: WEGU Magnitude of uncertainty score: | C21: 0
B22: CAAU Magnitude of uncertainty score: | C22: 0 | D22: OPTIONAL
A23: Fisheries
A24: Hypothesis 3: Commercial and recreational fishery equipment entangles/entraps individuals and reduces juvenile survival and/or adult survival.
B25: ASSP Magnitude of uncertainty score: | C25: 1
B26: BRPE Magnitude of uncertainty score: | C26: 0
B27: SCMU Magnitude of uncertainty score: | C27: 1
B28: SNPL Magnitude of uncertainty score: | C28: =IF('1. Relevance (a)'!C31=0, "NA", "") -> NA
B29: WEGU Magnitude of uncertainty score: | C29: 1
B30: CAAU Magnitude of uncertainty score: | C30: 1 | D30: OPTIONAL
A31: Hypothesis 4: Overfishing from commercial and recreational fisheries reduces foraging availability and/or quality, which reduces reproductive success, juvenile survival and/or adult survival.
B32: ASSP Magnitude of uncertainty score: | C32: 2
B33: BRPE Magnitude of uncertainty score: | C33: 0
B34: SCMU Magnitude of uncertainty score: | C34: 2
B35: SNPL Magnitude of uncertainty score: | C35: =IF('1. Relevance (a)'!C38=0, "NA", "") -> NA
B36: WEGU Magnitude of uncertainty score: | C36: 1
B37: CAAU Magnitude of uncertainty score: | C37: 1 | D37: OPTIONAL
A38: Harmful native species interaction
A39: Hypothesis 5: Native predators (island deer mouse, island spotted skunk, island fox, common raven, barn owl, peregrine falcon) predate eggs, chicks, and/or breeding adults, which reduces reproductive success and/or adult survival.
B40: ASSP Magnitude of uncertainty score: | C40: 0
...

Sheet 4. Reducibility
A1: Reducibility
A2: What is the potential to reduce uncertainty regarding the validity of this hypothesis, i.e., to reduce uncertainty regarding whether this hypothesis is having an effect on the population and to what degree?
A3: Consider the costs, logistics, and feasibility of designing an experimental or observational study that could lead to meaningful results within a relevant management timeframe of 30 years.
A4: Answer this question independent of the magnitude of uncertainty; in other words, answer this question assuming you do not know the effect of the hypothesis on the population.
A5: Score of 0: The uncertainty about this hypothesis is unlikely to be reduced within a relevant management timeframe due to the expected cost, logistics, and ability to obtain necessary data.
A6: Score of 1: The uncertainty about this hypothesis could be reduced by approximately 25% within a relevant management timeframe based on the expected cost, logistics, and ability to obtain necessary data.
A7: Score of 2: The uncertainty about this hypothesis could be reduced by approximately 50% within a relevant management timeframe based on the expected cost, logistics, and ability to obtain necessary data.
A8: Score of 3: The uncertainty about this hypothesis could be reduced by approximately 75% within a relevant management timeframe based on the expected cost, logistics, and ability to obtain necessary data.
A9: Score of 4: The uncertainty about this hypothesis could be mostly or completely reduced within a relevant management timeframe based on the expected cost, logistics, and ability to obtain necessary data.
A10: Hypothesis 1: Low overflights disturb breeding colonies and reduce reproductive success.
B11: ASSP Reducibility score: | C11: =IF('1. Relevance (a)'!C13=0, "NA", "") -> NA
B12: BRPE Reducibility score: | C12: 4
B13: SCMU Reducibility score: | C13: =IF('1. Relevance (a)'!C15=0, "NA", "") -> NA
B14: SNPL Reducibility score: | C14: =IF('1. Relevance (a)'!C16=0, "NA", "") -> NA
B15: WEGU Reducibility score: | C15: 4
B16: CAAU Reducibility score: | C16: =IF('1. Relevance (a)'!C18=0, "NA", "") -> NA | D16: OPTIONAL
A17: Hypothesis 2: Recreation causes disturbance to breeding colonies and reduces reproductive success.
B18: ASSP Reducibility score: | C18: 3
B19: BRPE Reducibility score: | C19: 3
B20: SCMU Reducibility score: | C20: 3
B21: SNPL Reducibility score: | C21: 3
B22: WEGU Reducibility score: | C22: 3
B23: CAAU Reducibility score: | C23: 3 | D23: OPTIONAL
A24: Fisheries
A25: Hypothesis 3: Commercial and recreational fishery equipment entangles/entraps individuals and reduces juvenile survival and/or adult survival.
B26: ASSP Reducibility score: | C26: 3
B27: BRPE Reducibility score: | C27: 3
B28: SCMU Reducibility score: | C28: 3
B29: SNPL Reducibility score: | C29: =IF('1. Relevance (a)'!C31=0, "NA", "") -> NA
B30: WEGU Reducibility score: | C30: 3
B31: CAAU Reducibility score: | C31: 3 | D31: OPTIONAL
A32: Hypothesis 4: Overfishing from commercial and recreational fisheries reduces foraging availability and/or quality, which reduces reproductive success, juvenile survival and/or adult survival.
B33: ASSP Reducibility score: | C33: 3
B34: BRPE Reducibility score: | C34: 3
B35: SCMU Reducibility score: | C35: 3
B36: SNPL Reducibility score: | C36: =IF('1. Relevance (a)'!C38=0, "NA", "") -> NA
B37: WEGU Reducibility score: | C37: 3
B38: CAAU Reducibility score: | C38: 3 | D38: OPTIONAL
A39: Harmful native species interaction
A40: Hypothesis 5: Native predators (island deer mouse, island spotted skunk, island fox, common raven, barn owl, peregrine falcon) predate eggs, chicks, and/or breeding adults, which reduces reproductive success and/or adult survival.
...

Sheet 5. Personal Confidence
A1: Personal Confidence
A2: What is your personal level of confidence, given your expertise and experience, in scoring this hypothesis for this particular species?
A3: Score of 0: I am the least confident in my response for this hypothesis and species.
A4: Score of 1: I am moderately confident in my response for this hypothesis and species.
A5: Score of 2: I am most confident in my response for this hypothesis and species.
A6: Disturbance
A7: Hypothesis 1: Low overflights disturb breeding colonies and reduce reproductive success.
B8: ASSP Confidence score: | C8: 2
B9: BRPE Confidence score: | C9: 2
B10: SCMU Confidence score: | C10: 2
B11: SNPL Confidence score: | C11: 0
B12: WEGU Confidence score: | C12: 2
B13: CAAU Confidence score: | C13: 2 | D13: OPTIONAL
A14: Hypothesis 2: Recreation causes disturbance to breeding colonies and reduces reproductive success.
B15: ASSP Confidence score: | C15: 2
B16: BRPE Confidence score: | C16: 2
B17: SCMU Confidence score: | C17: 2
B18: SNPL Confidence score: | C18: 1
B19: WEGU Confidence score: | C19: 2
B20: CAAU Confidence score: | C20: 2 | D20: OPTIONAL
A21: Fisheries
A22: Hypothesis 3: Commercial and recreational fishery equipment entangles/entraps individuals and reduces juvenile survival and/or adult survival.
B23: ASSP Confidence score: | C23: 2
B24: BRPE Confidence score: | C24: 2
B25: SCMU Confidence score: | C25: 1
B26: SNPL Confidence score: | C26: 0
B27: WEGU Confidence score: | C27: 1
B28: CAAU Confidence score: | C28: 1 | D28: OPTIONAL
A29: Hypothesis 4: Overfishing from commercial and recreational fisheries reduces foraging availability and/or quality, which reduces reproductive success, juvenile survival and/or adult survival.
B30: ASSP Confidence score: | C30: 1
B31: BRPE Confidence score: | C31: 2
B32: SCMU Confidence score: | C32: 1
B33: SNPL Confidence score: | C33: 0
B34: WEGU Confidence score: | C34: 2
B35: CAAU Confidence score: | C35: 1 | D35: OPTIONAL
A36: Harmful native species interaction
A37: Hypothesis 5: Native predators (island deer mouse, island spotted skunk, island fox, common raven, barn owl, peregrine falcon) predate eggs, chicks, and/or breeding adults, which reduces reproductive success and/or adult survival.
B38: ASSP Confidence score: | C38: 2
B39: BRPE Confidence score: | C39: 2
B40: SCMU Confidence score: | C40: 2
...
